<?xml version="1.0"?>

<robot xmlns:xacro="http://www.ros.org/wiki/xacro">
    <xacro:include filename="$(find dji_m100_description)/urdf/gimbal_joints.xacro"/>
    
    <xacro:macro name="dji_m100_gimbal">
        <revolute_gimbal_joint 
            name="gimbal_roll_joint"
            parent="base_link"
            child="gimbal_roll_link"
            lower_limit="-0.48"
            upper_limit="0.48"
            axis_xyz="1 0 0"
            origin_xyz="-0.1 0 -0.04"
            />
        <transmission name="trans_roll">
            <type>transmission_interface/SimpleTransmission</type>
            <joint name="gimbal_roll_joint">
                <hardwareInterface>hardware_interface/EffortJointInterface</hardwareInterface>
            </joint>
            <actuator name="motor_roll">
                <hardwareInterface>hardware_interface/EffortJointInterface</hardwareInterface>
                <mechanicalReduction>1</mechanicalReduction>
            </actuator>
        </transmission>

        <link name="gimbal_roll_link">
            <inertial>
                <mass value="0.1" />
                <origin xyz="-0.1 0 -0.04" rpy="0 0 0" />
                <inertia ixx="0.0" ixy="0" ixz="0" iyy="0.0" iyz="0" izz="0.0" />
            </inertial>
            <visual>
                <geometry>
                    <box size="0.0001 0.0001 0.0001" />
                </geometry>
            </visual>
        </link>

        <revolute_gimbal_joint 
            name="gimbal_pitch_joint"
            parent="gimbal_roll_link"
            child="gimbal_pitch_link"
            lower_limit="-0.48"
            upper_limit="0.48"
            axis_xyz="0 1 0"
            origin_xyz="0 0 0"
            />
        <transmission name="trans_pitch">
            <type>transmission_interface/SimpleTransmission</type>
            <joint name="gimbal_pitch_joint">
                <hardwareInterface>hardware_interface/EffortJointInterface</hardwareInterface>
            </joint>
            <actuator name="motor_pitch">
                <hardwareInterface>hardware_interface/EffortJointInterface</hardwareInterface>
                <mechanicalReduction>1</mechanicalReduction>
            </actuator>
        </transmission>

        <link name="gimbal_pitch_link">
            <inertial>
                <mass value="0.1" />
                <origin xyz="0 0 0" rpy="0 0 0" />
                <inertia ixx="0.0" ixy="0" ixz="0" iyy="0.0" iyz="0" izz="0.0" />
            </inertial>
            <visual>
                <geometry>
                <box size="0.001 0.0001 0.0001" />
                </geometry>
            </visual>
        </link>
        <revolute_gimbal_joint 
            name="gimbal_yaw_joint"
            parent="gimbal_pitch_link"
            child="gimbal_yaw_link"
            lower_limit="-3.14"
            upper_limit="3.14"
            axis_xyz="0 0 1"
            origin_xyz="0 0 0"
            />
        <transmission name="trans_yaw">
            <type>transmission_interface/SimpleTransmission</type>
            <joint name="gimbal_yaw_joint">
                <hardwareInterface>hardware_interface/EffortJointInterface</hardwareInterface>
            </joint>
            <actuator name="motor_yaw">
                <hardwareInterface>hardware_interface/EffortJointInterface</hardwareInterface>
                <mechanicalReduction>1</mechanicalReduction>
            </actuator>
        </transmission>

        <link name="gimbal_yaw_link">
            <inertial>
                <mass value="0.1" />
                <origin xyz="0 0 0" rpy="0 0 ${-M_PI}" />
                <inertia ixx="0.0" ixy="0" ixz="0" iyy="0.0" iyz="0" izz="0.0" />
            </inertial>
            <visual>
                <origin xyz="0 0 0" rpy="0 0 ${-M_PI}" />
                <geometry>
                    <mesh filename="package://dji_m100_description/meshes/dji_m100/gimbal.dae"/>
                </geometry>
            </visual>
            <collision>
                <origin xyz="0 0 0" rpy="0 0 ${-M_PI}" />
                <geometry>
                <mesh filename="package://dji_m100_description/meshes/dji_m100/gimbal.stl"/>
                </geometry>
            </collision>
        </link>
        <joint name="camera_joint" type="continuous">
            <parent link="gimbal_yaw_link" />
            <child link="camera_link" />
            <axis xyz="0 0 1" />
            <dynamics damping="0.0" friction="0.0" />
        </joint>
        <link name="camera_link">
        </link>

        <joint name="camera_optical_joint" type="fixed">
            <origin xyz="0 0 0" rpy="${-M_PI/2} 0.0 ${-M_PI/2}" />
            <parent link="camera_link" />
            <child link="camera_optical_frame"/>
        </joint>
        <gazebo reference="camera_optical_joint">
            <preserveFixedJoint>true</preserveFixedJoint>
        </gazebo>
        <link name="camera_optical_frame">
        </link>
        
        <gazebo reference="gimbal_yaw_link">
            <sensor type="camera" name="camera_camera_sensor">
                <update_rate>10</update_rate>
                <camera>
                <!-- <pose>0.027 0 -0.027 0 1.57 0</pose> -->
                <!-- <pose>0.027 0 -0.027 0 1.57 0</pose> -->
                <pose>0.107 0 -0.227 0 0 ${M_PI}</pose>
                <horizontal_fov>${94 * M_PI/180.0}</horizontal_fov>
                <image>
                    <format>R8G8B8</format>
                    <width>640</width>
                    <height>480</height>
                </image>
                <clip>
                    <near>0.01</near>
                    <far>100</far>
                </clip>
                </camera>

                <plugin name="camera_controller" filename="libgazebo_ros_camera.so">
                <cameraName>camera</cameraName>
                <alwaysOn>true</alwaysOn>
                <updateRate>10</updateRate>
                
                <imageTopicName>dji_sdk/image_raw</imageTopicName>
                <cameraInfoTopicName>dji_sdk/camera_info</cameraInfoTopicName>
                <frameName>camera_optical_frame</frameName>
                </plugin>
            </sensor>
        </gazebo>
    </xacro:macro>
</robot>

